Traceback (most recent call last):
  File "/home/shaytaan/Desktop/ServerTest/ServerUDP.py", line 4, in <module>
    serverSocket.bind(('', serverPort))
OSError: [Errno 98] Address already in use
Traceback (most recent call last):
  File "/home/shaytaan/Desktop/ServerTest/ServerUDP.py", line 4, in <module>
    serverSocket.bind(('', serverPort))
OSError: [Errno 98] Address already in use
